~/workspace$ gunicorn --bind 0.0.0.0:5000 --workers 2 --timeout 120 main:app
[2025-05-29 11:54:04 +0000] [2635] [INFO] Starting gunicorn 21.2.0
[2025-05-29 11:54:04 +0000] [2635] [INFO] Listening at: http://0.0.0.0:5000 (2635)
[2025-05-29 11:54:04 +0000] [2635] [INFO] Using worker: sync
[2025-05-29 11:54:04 +0000] [2640] [INFO] Booting worker with pid: 2640
[2025-05-29 11:54:04 +0000] [2641] [INFO] Booting worker with pid: 2641
[2025-05-29 11:54:04 +0000] [2635] [INFO] Handling signal: winch
[2025-05-29 11:54:05 +0000] [2640] [ERROR] Exception in worker process
Traceback (most recent call last):
  File "/home/runner/workspace/.pythonlibs/lib/python3.11/site-packages/gunicorn/arbiter.py", line 609, in spawn_worker
    worker.init_process()
  File "/home/runner/workspace/.pythonlibs/lib/python3.11/site-packages/gunicorn/workers/base.py", line 134, in init_process
    self.load_wsgi()
  File "/home/runner/workspace/.pythonlibs/lib/python3.11/site-packages/gunicorn/workers/base.py", line 146, in load_wsgi
    self.wsgi = self.app.wsgi()
                ^^^^^^^^^^^^^^^
  File "/home/runner/workspace/.pythonlibs/lib/python3.11/site-packages/gunicorn/app/base.py", line 67, in wsgi
    self.callable = self.load()
                    ^^^^^^^^^^^
  File "/home/runner/workspace/.pythonlibs/lib/python3.11/site-packages/gunicorn/app/wsgiapp.py", line 58, in load
    return self.load_wsgiapp()
           ^^^^^^^^^^^^^^^^^^^
  File "/home/runner/workspace/.pythonlibs/lib/python3.11/site-packages/gunicorn/app/wsgiapp.py", line 48, in load_wsgiapp
    return util.import_app(self.app_uri)
           ^^^^^^^^^^^^^^^^^^^^^^^^^^^^^
  File "/home/runner/workspace/.pythonlibs/lib/python3.11/site-packages/gunicorn/util.py", line 371, in import_app
    mod = importlib.import_module(module)
          ^^^^^^^^^^^^^^^^^^^^^^^^^^^^^^^
  File "/nix/store/clx0mcir7qw8zk36zbr4jra789g3knf6-python3-3.11.10/lib/python3.11/importlib/__init__.py", line 126, in import_module
    return _bootstrap._gcd_import(name[level:], package, level)
           ^^^^^^^^^^^^^^^^^^^^^^^^^^^^^^^^^^^^^^^^^^^^^^^^^^^^
  File "<frozen importlib._bootstrap>", line 1204, in _gcd_import
  File "<frozen importlib._bootstrap>", line 1176, in _find_and_load
  File "<frozen importlib._bootstrap>", line 1147, in _find_and_load_unlocked
  File "<frozen importlib._bootstrap>", line 690, in _load_unlocked
  File "<frozen importlib._bootstrap_external>", line 940, in exec_module
  File "<frozen importlib._bootstrap>", line 241, in _call_with_frames_removed
  File "/home/runner/workspace/main.py", line 6, in <module>
    from app.backend import app
  File "/home/runner/workspace/app/backend.py", line 21, in <module>
    from app.utils.marketplace import marketplace_service, reward_service
  File "/home/runner/workspace/app/utils/marketplace.py", line 303, in <module>
    marketplace_service = MarketplaceService()
                          ^^^^^^^^^^^^^^^^^^^^
  File "/home/runner/workspace/app/utils/marketplace.py", line 17, in __init__
    self.cardano = get_koios_client()
                   ^^^^^^^^^^^^^^^^^^
  File "/home/runner/workspace/app/utils/cardano.py", line 149, in get_koios_client
    return KoiosClient()
           ^^^^^^^^^^^^^
  File "/home/runner/workspace/app/utils/cardano.py", line 15, in __init__
    self.base_url = base_url or current_app.config['KOIOS_API_URL']
                                ^^^^^^^^^^^^^^^^^^
  File "/home/runner/workspace/.pythonlibs/lib/python3.11/site-packages/werkzeug/local.py", line 311, in __get__
    obj = instance._get_current_object()
          ^^^^^^^^^^^^^^^^^^^^^^^^^^^^^^
  File "/home/runner/workspace/.pythonlibs/lib/python3.11/site-packages/werkzeug/local.py", line 508, in _get_current_object
    raise RuntimeError(unbound_message) from None
RuntimeError: Working outside of application context.

This typically means that you attempted to use functionality that needed
the current application. To solve this, set up an application context
with app.app_context(). See the documentation for more information.
[2025-05-29 11:54:05 +0000] [2640] [INFO] Worker exiting (pid: 2640)
[2025-05-29 11:54:05 +0000] [2641] [ERROR] Exception in worker process
Traceback (most recent call last):
  File "/home/runner/workspace/.pythonlibs/lib/python3.11/site-packages/gunicorn/arbiter.py", line 609, in spawn_worker
    worker.init_process()
  File "/home/runner/workspace/.pythonlibs/lib/python3.11/site-packages/gunicorn/workers/base.py", line 134, in init_process
    self.load_wsgi()
  File "/home/runner/workspace/.pythonlibs/lib/python3.11/site-packages/gunicorn/workers/base.py", line 146, in load_wsgi
    self.wsgi = self.app.wsgi()
                ^^^^^^^^^^^^^^^
  File "/home/runner/workspace/.pythonlibs/lib/python3.11/site-packages/gunicorn/app/base.py", line 67, in wsgi
    self.callable = self.load()
                    ^^^^^^^^^^^
  File "/home/runner/workspace/.pythonlibs/lib/python3.11/site-packages/gunicorn/app/wsgiapp.py", line 58, in load
    return self.load_wsgiapp()
           ^^^^^^^^^^^^^^^^^^^
  File "/home/runner/workspace/.pythonlibs/lib/python3.11/site-packages/gunicorn/app/wsgiapp.py", line 48, in load_wsgiapp
    return util.import_app(self.app_uri)
           ^^^^^^^^^^^^^^^^^^^^^^^^^^^^^
  File "/home/runner/workspace/.pythonlibs/lib/python3.11/site-packages/gunicorn/util.py", line 371, in import_app
    mod = importlib.import_module(module)
          ^^^^^^^^^^^^^^^^^^^^^^^^^^^^^^^
  File "/nix/store/clx0mcir7qw8zk36zbr4jra789g3knf6-python3-3.11.10/lib/python3.11/importlib/__init__.py", line 126, in import_module
    return _bootstrap._gcd_import(name[level:], package, level)
           ^^^^^^^^^^^^^^^^^^^^^^^^^^^^^^^^^^^^^^^^^^^^^^^^^^^^
  File "<frozen importlib._bootstrap>", line 1204, in _gcd_import
  File "<frozen importlib._bootstrap>", line 1176, in _find_and_load
  File "<frozen importlib._bootstrap>", line 1147, in _find_and_load_unlocked
  File "<frozen importlib._bootstrap>", line 690, in _load_unlocked
  File "<frozen importlib._bootstrap_external>", line 940, in exec_module
  File "<frozen importlib._bootstrap>", line 241, in _call_with_frames_removed
  File "/home/runner/workspace/main.py", line 6, in <module>
    from app.backend import app
  File "/home/runner/workspace/app/backend.py", line 21, in <module>
    from app.utils.marketplace import marketplace_service, reward_service
  File "/home/runner/workspace/app/utils/marketplace.py", line 303, in <module>
    marketplace_service = MarketplaceService()
                          ^^^^^^^^^^^^^^^^^^^^
  File "/home/runner/workspace/app/utils/marketplace.py", line 17, in __init__
    self.cardano = get_koios_client()
                   ^^^^^^^^^^^^^^^^^^
  File "/home/runner/workspace/app/utils/cardano.py", line 149, in get_koios_client
    return KoiosClient()
           ^^^^^^^^^^^^^
  File "/home/runner/workspace/app/utils/cardano.py", line 15, in __init__
    self.base_url = base_url or current_app.config['KOIOS_API_URL']
                                ^^^^^^^^^^^^^^^^^^
  File "/home/runner/workspace/.pythonlibs/lib/python3.11/site-packages/werkzeug/local.py", line 311, in __get__
    obj = instance._get_current_object()
          ^^^^^^^^^^^^^^^^^^^^^^^^^^^^^^
  File "/home/runner/workspace/.pythonlibs/lib/python3.11/site-packages/werkzeug/local.py", line 508, in _get_current_object
    raise RuntimeError(unbound_message) from None
RuntimeError: Working outside of application context.

This typically means that you attempted to use functionality that needed
the current application. To solve this, set up an application context
with app.app_context(). See the documentation for more information.
[2025-05-29 11:54:05 +0000] [2641] [INFO] Worker exiting (pid: 2641)
[2025-05-29 11:54:05 +0000] [2635] [ERROR] Worker (pid:2640) exited with code 3
[2025-05-29 11:54:05 +0000] [2635] [ERROR] Worker (pid:2641) was sent SIGTERM!
[2025-05-29 11:54:06 +0000] [2635] [ERROR] Shutting down: Master
[2025-05-29 11:54:06 +0000] [2635] [ERROR] Reason: Worker failed to boot.